[2025-02-28T15:38:45.913+0000] {local_task_job_runner.py:123} INFO - ::group::Pre task execution logs
[2025-02-28T15:38:45.941+0000] {taskinstance.py:2614} INFO - Dependencies all met for dep_context=non-requeueable deps ti=<TaskInstance: etl_scrapper_pipeline.scrapping_data manual__2025-02-28T15:33:16.089080+00:00 [queued]>
[2025-02-28T15:38:45.954+0000] {taskinstance.py:2614} INFO - Dependencies all met for dep_context=requeueable deps ti=<TaskInstance: etl_scrapper_pipeline.scrapping_data manual__2025-02-28T15:33:16.089080+00:00 [queued]>
[2025-02-28T15:38:45.955+0000] {taskinstance.py:2867} INFO - Starting attempt 3 of 4
[2025-02-28T15:38:45.974+0000] {taskinstance.py:2890} INFO - Executing <Task(PythonOperator): scrapping_data> on 2025-02-28 15:33:16.089080+00:00
[2025-02-28T15:38:45.987+0000] {warnings.py:112} WARNING - /home/***/.local/lib/python3.12/site-packages/***/task/task_runner/standard_task_runner.py:70: DeprecationWarning: This process (pid=243) is multi-threaded, use of fork() may lead to deadlocks in the child.
  pid = os.fork()

[2025-02-28T15:38:45.990+0000] {standard_task_runner.py:72} INFO - Started process 245 to run task
[2025-02-28T15:38:45.989+0000] {standard_task_runner.py:104} INFO - Running: ['***', 'tasks', 'run', 'etl_scrapper_pipeline', 'scrapping_data', 'manual__2025-02-28T15:33:16.089080+00:00', '--job-id', '19', '--raw', '--subdir', 'DAGS_FOLDER/etl_dags.py', '--cfg-path', '/tmp/tmprqkk253t']
[2025-02-28T15:38:45.992+0000] {standard_task_runner.py:105} INFO - Job 19: Subtask scrapping_data
[2025-02-28T15:38:46.068+0000] {task_command.py:467} INFO - Running <TaskInstance: etl_scrapper_pipeline.scrapping_data manual__2025-02-28T15:33:16.089080+00:00 [running]> on host 081ded626b25
[2025-02-28T15:38:46.182+0000] {taskinstance.py:3134} INFO - Exporting env vars: AIRFLOW_CTX_DAG_OWNER='***' AIRFLOW_CTX_DAG_ID='etl_scrapper_pipeline' AIRFLOW_CTX_TASK_ID='scrapping_data' AIRFLOW_CTX_EXECUTION_DATE='2025-02-28T15:33:16.089080+00:00' AIRFLOW_CTX_TRY_NUMBER='3' AIRFLOW_CTX_DAG_RUN_ID='manual__2025-02-28T15:33:16.089080+00:00'
[2025-02-28T15:38:46.184+0000] {logging_mixin.py:190} INFO - Task instance is in running state
[2025-02-28T15:38:46.184+0000] {logging_mixin.py:190} INFO -  Previous state of the Task instance: queued
[2025-02-28T15:38:46.185+0000] {logging_mixin.py:190} INFO - Current task name:scrapping_data state:running start_date:2025-02-28 15:38:45.942357+00:00
[2025-02-28T15:38:46.186+0000] {logging_mixin.py:190} INFO - Dag name:etl_scrapper_pipeline and current dag run status:running
[2025-02-28T15:38:46.186+0000] {taskinstance.py:732} INFO - ::endgroup::
[2025-02-28T15:38:46.187+0000] {etl_dags.py:29} INFO - Scraping page 1: https://www.amazon.com/s?k=macbook&page=1&crid=3CHS3289UBR9B&qid=1740647689&sprefix=macb%2Caps%2C322&xpid=h062vM3nTWtUZ&ref=sr_pg_1
[2025-02-28T15:38:50.196+0000] {etl_dags.py:35} ERROR - Failed to retrieve page 1: HTTPSConnectionPool(host='www.amazon.com', port=443): Max retries exceeded with url: /s?k=macbook&page=1&crid=3CHS3289UBR9B&qid=1740647689&sprefix=macb%2Caps%2C322&xpid=h062vM3nTWtUZ&ref=sr_pg_1 (Caused by NewConnectionError('<urllib3.connection.HTTPSConnection object at 0x7f9ee8c06690>: Failed to establish a new connection: [Errno 101] Network is unreachable'))
[2025-02-28T15:38:50.197+0000] {etl_dags.py:29} INFO - Scraping page 2: https://www.amazon.com/s?k=macbook&page=2&crid=3CHS3289UBR9B&qid=1740647689&sprefix=macb%2Caps%2C322&xpid=h062vM3nTWtUZ&ref=sr_pg_2
[2025-02-28T15:38:54.202+0000] {etl_dags.py:35} ERROR - Failed to retrieve page 2: HTTPSConnectionPool(host='www.amazon.com', port=443): Max retries exceeded with url: /s?k=macbook&page=2&crid=3CHS3289UBR9B&qid=1740647689&sprefix=macb%2Caps%2C322&xpid=h062vM3nTWtUZ&ref=sr_pg_2 (Caused by NewConnectionError('<urllib3.connection.HTTPSConnection object at 0x7f9ee8a6ef90>: Failed to establish a new connection: [Errno 101] Network is unreachable'))
[2025-02-28T15:38:54.202+0000] {etl_dags.py:29} INFO - Scraping page 3: https://www.amazon.com/s?k=macbook&page=3&crid=3CHS3289UBR9B&qid=1740647689&sprefix=macb%2Caps%2C322&xpid=h062vM3nTWtUZ&ref=sr_pg_3
[2025-02-28T15:38:56.109+0000] {local_task_job_runner.py:346} WARNING - State of this instance has been externally set to failed. Terminating instance.
[2025-02-28T15:38:56.110+0000] {local_task_job_runner.py:245} INFO - ::endgroup::
[2025-02-28T15:38:56.114+0000] {process_utils.py:132} INFO - Sending 15 to group 245. PIDs of all processes in the group: [245]
[2025-02-28T15:38:56.114+0000] {process_utils.py:87} INFO - Sending the signal 15 to group 245
[2025-02-28T15:38:57.295+0000] {taskinstance.py:3094} ERROR - Received SIGTERM. Terminating subprocesses.
[2025-02-28T15:38:57.311+0000] {taskinstance.py:3095} ERROR - Stacktrace: 
  File "/home/***/.local/bin/***", line 8, in <module>
    sys.exit(main())
  File "/home/***/.local/lib/python3.12/site-packages/***/__main__.py", line 62, in main
    args.func(args)
  File "/home/***/.local/lib/python3.12/site-packages/***/cli/cli_config.py", line 49, in command
    return func(*args, **kwargs)
  File "/home/***/.local/lib/python3.12/site-packages/***/utils/cli.py", line 116, in wrapper
    return f(*args, **kwargs)
  File "/home/***/.local/lib/python3.12/site-packages/***/providers/celery/cli/celery_command.py", line 64, in wrapper
    providers_configuration_loaded(func)(*args, **kwargs)
  File "/home/***/.local/lib/python3.12/site-packages/***/utils/providers_configuration_loader.py", line 55, in wrapped_function
    return func(*args, **kwargs)
  File "/home/***/.local/lib/python3.12/site-packages/***/providers/celery/cli/celery_command.py", line 237, in worker
    _run_command_with_daemon_option(
  File "/home/***/.local/lib/python3.12/site-packages/***/providers/celery/cli/celery_command.py", line 50, in _run_command_with_daemon_option
    run_command_with_daemon_option(*args, **kwargs)
  File "/home/***/.local/lib/python3.12/site-packages/***/cli/commands/daemon_utils.py", line 86, in run_command_with_daemon_option
    callback()
  File "/home/***/.local/lib/python3.12/site-packages/***/providers/celery/cli/celery_command.py", line 230, in run_celery_worker
    celery_app.worker_main(options)
  File "/home/***/.local/lib/python3.12/site-packages/celery/app/base.py", line 391, in worker_main
    self.start(argv=argv)
  File "/home/***/.local/lib/python3.12/site-packages/celery/app/base.py", line 371, in start
    celery.main(args=argv, standalone_mode=False)
  File "/home/***/.local/lib/python3.12/site-packages/click/core.py", line 1082, in main
    rv = self.invoke(ctx)
  File "/home/***/.local/lib/python3.12/site-packages/click/core.py", line 1697, in invoke
    return _process_result(sub_ctx.command.invoke(sub_ctx))
  File "/home/***/.local/lib/python3.12/site-packages/click/core.py", line 1443, in invoke
    return ctx.invoke(self.callback, **ctx.params)
  File "/home/***/.local/lib/python3.12/site-packages/click/core.py", line 788, in invoke
    return __callback(*args, **kwargs)
  File "/home/***/.local/lib/python3.12/site-packages/click/decorators.py", line 33, in new_func
    return f(get_current_context(), *args, **kwargs)
  File "/home/***/.local/lib/python3.12/site-packages/celery/bin/base.py", line 135, in caller
    return f(ctx, *args, **kwargs)
  File "/home/***/.local/lib/python3.12/site-packages/celery/bin/worker.py", line 356, in worker
    worker.start()
  File "/home/***/.local/lib/python3.12/site-packages/celery/worker/worker.py", line 202, in start
    self.blueprint.start(self)
  File "/home/***/.local/lib/python3.12/site-packages/celery/bootsteps.py", line 116, in start
    step.start(parent)
  File "/home/***/.local/lib/python3.12/site-packages/celery/bootsteps.py", line 365, in start
    return self.obj.start()
  File "/home/***/.local/lib/python3.12/site-packages/celery/concurrency/base.py", line 130, in start
    self.on_start()
  File "/home/***/.local/lib/python3.12/site-packages/celery/concurrency/prefork.py", line 109, in on_start
    P = self._pool = Pool(processes=self.limit,
  File "/home/***/.local/lib/python3.12/site-packages/celery/concurrency/asynpool.py", line 464, in __init__
    super().__init__(processes, *args, **kwargs)
  File "/home/***/.local/lib/python3.12/site-packages/billiard/pool.py", line 1046, in __init__
    self._create_worker_process(i)
  File "/home/***/.local/lib/python3.12/site-packages/celery/concurrency/asynpool.py", line 482, in _create_worker_process
    return super()._create_worker_process(i)
  File "/home/***/.local/lib/python3.12/site-packages/billiard/pool.py", line 1158, in _create_worker_process
    w.start()
  File "/home/***/.local/lib/python3.12/site-packages/billiard/process.py", line 120, in start
    self._popen = self._Popen(self)
  File "/home/***/.local/lib/python3.12/site-packages/billiard/context.py", line 331, in _Popen
    return Popen(process_obj)
  File "/home/***/.local/lib/python3.12/site-packages/billiard/popen_fork.py", line 22, in __init__
    self._launch(process_obj)
  File "/home/***/.local/lib/python3.12/site-packages/billiard/popen_fork.py", line 77, in _launch
    code = process_obj._bootstrap()
  File "/home/***/.local/lib/python3.12/site-packages/billiard/process.py", line 323, in _bootstrap
    self.run()
  File "/home/***/.local/lib/python3.12/site-packages/billiard/process.py", line 110, in run
    self._target(*self._args, **self._kwargs)
  File "/home/***/.local/lib/python3.12/site-packages/billiard/pool.py", line 292, in __call__
    sys.exit(self.workloop(pid=pid))
  File "/home/***/.local/lib/python3.12/site-packages/billiard/pool.py", line 362, in workloop
    result = (True, prepare_result(fun(*args, **kwargs)))
  File "/home/***/.local/lib/python3.12/site-packages/celery/app/trace.py", line 651, in fast_trace_task
    R, I, T, Rstr = tasks[task].__trace__(
  File "/home/***/.local/lib/python3.12/site-packages/celery/app/trace.py", line 453, in trace_task
    R = retval = fun(*args, **kwargs)
  File "/home/***/.local/lib/python3.12/site-packages/celery/app/trace.py", line 736, in __protected_call__
    return self.run(*args, **kwargs)
  File "/home/***/.local/lib/python3.12/site-packages/***/providers/celery/executors/celery_executor_utils.py", line 139, in execute_command
    _execute_in_fork(command_to_exec, celery_task_id)
  File "/home/***/.local/lib/python3.12/site-packages/***/providers/celery/executors/celery_executor_utils.py", line 171, in _execute_in_fork
    args.func(args)
  File "/home/***/.local/lib/python3.12/site-packages/***/cli/cli_config.py", line 49, in command
    return func(*args, **kwargs)
  File "/home/***/.local/lib/python3.12/site-packages/***/utils/cli.py", line 116, in wrapper
    return f(*args, **kwargs)
  File "/home/***/.local/lib/python3.12/site-packages/***/cli/commands/task_command.py", line 483, in task_run
    task_return_code = _run_task_by_selected_method(args, _dag, ti)
  File "/home/***/.local/lib/python3.12/site-packages/***/cli/commands/task_command.py", line 254, in _run_task_by_selected_method
    return _run_task_by_local_task_job(args, ti)
  File "/home/***/.local/lib/python3.12/site-packages/***/cli/commands/task_command.py", line 322, in _run_task_by_local_task_job
    ret = run_job(job=job_runner.job, execute_callable=job_runner._execute)
  File "/home/***/.local/lib/python3.12/site-packages/***/utils/session.py", line 97, in wrapper
    return func(*args, session=session, **kwargs)
  File "/home/***/.local/lib/python3.12/site-packages/***/jobs/job.py", line 421, in run_job
    return execute_job(job, execute_callable=execute_callable)
  File "/home/***/.local/lib/python3.12/site-packages/***/jobs/job.py", line 450, in execute_job
    ret = execute_callable()
  File "/home/***/.local/lib/python3.12/site-packages/***/jobs/local_task_job_runner.py", line 171, in _execute
    self.task_runner.start()
  File "/home/***/.local/lib/python3.12/site-packages/***/task/task_runner/standard_task_runner.py", line 55, in start
    self.process = self._start_by_fork()
  File "/home/***/.local/lib/python3.12/site-packages/***/task/task_runner/standard_task_runner.py", line 117, in _start_by_fork
    ret = args.func(args, dag=self.dag)
  File "/home/***/.local/lib/python3.12/site-packages/***/cli/cli_config.py", line 49, in command
    return func(*args, **kwargs)
  File "/home/***/.local/lib/python3.12/site-packages/***/utils/cli.py", line 116, in wrapper
    return f(*args, **kwargs)
  File "/home/***/.local/lib/python3.12/site-packages/***/cli/commands/task_command.py", line 483, in task_run
    task_return_code = _run_task_by_selected_method(args, _dag, ti)
  File "/home/***/.local/lib/python3.12/site-packages/***/cli/commands/task_command.py", line 256, in _run_task_by_selected_method
    return _run_raw_task(args, ti)
  File "/home/***/.local/lib/python3.12/site-packages/***/cli/commands/task_command.py", line 341, in _run_raw_task
    return ti._run_raw_task(
  File "/home/***/.local/lib/python3.12/site-packages/***/utils/session.py", line 97, in wrapper
    return func(*args, session=session, **kwargs)
  File "/home/***/.local/lib/python3.12/site-packages/***/models/taskinstance.py", line 3006, in _run_raw_task
    return _run_raw_task(
  File "/home/***/.local/lib/python3.12/site-packages/***/models/taskinstance.py", line 274, in _run_raw_task
    TaskInstance._execute_task_with_callbacks(
  File "/home/***/.local/lib/python3.12/site-packages/***/models/taskinstance.py", line 3161, in _execute_task_with_callbacks
    result = self._execute_task(context, task_orig)
  File "/home/***/.local/lib/python3.12/site-packages/***/models/taskinstance.py", line 3185, in _execute_task
    return _execute_task(self, context, task_orig)
  File "/home/***/.local/lib/python3.12/site-packages/***/models/taskinstance.py", line 768, in _execute_task
    result = _execute_callable(context=context, **execute_callable_kwargs)
  File "/home/***/.local/lib/python3.12/site-packages/***/models/taskinstance.py", line 734, in _execute_callable
    return ExecutionCallableRunner(
  File "/home/***/.local/lib/python3.12/site-packages/***/utils/operator_helpers.py", line 252, in run
    return self.func(*args, **kwargs)
  File "/home/***/.local/lib/python3.12/site-packages/***/models/baseoperator.py", line 424, in wrapper
    return func(self, *args, **kwargs)
  File "/home/***/.local/lib/python3.12/site-packages/***/operators/python.py", line 238, in execute
    return_value = self.execute_callable()
  File "/home/***/.local/lib/python3.12/site-packages/***/operators/python.py", line 256, in execute_callable
    return runner.run(*self.op_args, **self.op_kwargs)
  File "/home/***/.local/lib/python3.12/site-packages/***/utils/operator_helpers.py", line 252, in run
    return self.func(*args, **kwargs)
  File "/opt/***/dags/etl_dags.py", line 32, in extract_file
    response = requests.get(url, headers=headers)
  File "/home/***/.local/lib/python3.12/site-packages/requests/api.py", line 73, in get
    return request("get", url, params=params, **kwargs)
  File "/home/***/.local/lib/python3.12/site-packages/requests/api.py", line 59, in request
    return session.request(method=method, url=url, **kwargs)
  File "/home/***/.local/lib/python3.12/site-packages/requests/sessions.py", line 589, in request
    resp = self.send(prep, **send_kwargs)
  File "/home/***/.local/lib/python3.12/site-packages/requests/sessions.py", line 703, in send
    r = adapter.send(request, **kwargs)
  File "/home/***/.local/lib/python3.12/site-packages/requests/adapters.py", line 667, in send
    resp = conn.urlopen(
  File "/home/***/.local/lib/python3.12/site-packages/urllib3/connectionpool.py", line 787, in urlopen
    response = self._make_request(
  File "/home/***/.local/lib/python3.12/site-packages/urllib3/connectionpool.py", line 464, in _make_request
    self._validate_conn(conn)
  File "/home/***/.local/lib/python3.12/site-packages/urllib3/connectionpool.py", line 1093, in _validate_conn
    conn.connect()
  File "/home/***/.local/lib/python3.12/site-packages/urllib3/connection.py", line 704, in connect
    self.sock = sock = self._new_conn()
  File "/home/***/.local/lib/python3.12/site-packages/urllib3/connection.py", line 198, in _new_conn
    sock = connection.create_connection(
  File "/home/***/.local/lib/python3.12/site-packages/urllib3/util/connection.py", line 60, in create_connection
    for res in socket.getaddrinfo(host, port, family, socket.SOCK_STREAM):
  File "/usr/local/lib/python3.12/socket.py", line 978, in getaddrinfo
    for res in _socket.getaddrinfo(host, port, family, type, proto, flags):
  File "/home/***/.local/lib/python3.12/site-packages/***/models/taskinstance.py", line 3095, in signal_handler
    self.log.error("Stacktrace: \n%s", "".join(traceback.format_stack()))

[2025-02-28T15:38:57.357+0000] {taskinstance.py:341} INFO - ::group::Post task execution logs
[2025-02-28T15:38:57.385+0000] {process_utils.py:80} INFO - Process psutil.Process(pid=245, status='terminated', exitcode=0, started='15:38:45') (245) terminated with exit code 0
