[2025-03-01T08:55:23.659+0000] {local_task_job_runner.py:123} INFO - ::group::Pre task execution logs
[2025-03-01T08:55:23.686+0000] {taskinstance.py:2614} INFO - Dependencies all met for dep_context=non-requeueable deps ti=<TaskInstance: etl_scrapper_pipeline.scrapping_data manual__2025-03-01T08:55:16.382449+00:00 [queued]>
[2025-03-01T08:55:23.703+0000] {taskinstance.py:2614} INFO - Dependencies all met for dep_context=requeueable deps ti=<TaskInstance: etl_scrapper_pipeline.scrapping_data manual__2025-03-01T08:55:16.382449+00:00 [queued]>
[2025-03-01T08:55:23.705+0000] {taskinstance.py:2867} INFO - Starting attempt 1 of 2
[2025-03-01T08:55:23.731+0000] {taskinstance.py:2890} INFO - Executing <Task(PythonOperator): scrapping_data> on 2025-03-01 08:55:16.382449+00:00
[2025-03-01T08:55:23.743+0000] {warnings.py:112} WARNING - /home/***/.local/lib/python3.12/site-packages/***/task/task_runner/standard_task_runner.py:70: DeprecationWarning: This process (pid=119) is multi-threaded, use of fork() may lead to deadlocks in the child.
  pid = os.fork()

[2025-03-01T08:55:23.745+0000] {standard_task_runner.py:104} INFO - Running: ['***', 'tasks', 'run', 'etl_scrapper_pipeline', 'scrapping_data', 'manual__2025-03-01T08:55:16.382449+00:00', '--job-id', '150', '--raw', '--subdir', 'DAGS_FOLDER/etl_dags.py', '--cfg-path', '/tmp/tmpxss66ho8']
[2025-03-01T08:55:23.746+0000] {standard_task_runner.py:72} INFO - Started process 129 to run task
[2025-03-01T08:55:23.747+0000] {standard_task_runner.py:105} INFO - Job 150: Subtask scrapping_data
[2025-03-01T08:55:23.809+0000] {task_command.py:467} INFO - Running <TaskInstance: etl_scrapper_pipeline.scrapping_data manual__2025-03-01T08:55:16.382449+00:00 [running]> on host 786e1105915a
[2025-03-01T08:55:23.904+0000] {taskinstance.py:3134} INFO - Exporting env vars: AIRFLOW_CTX_DAG_OWNER='***' AIRFLOW_CTX_DAG_ID='etl_scrapper_pipeline' AIRFLOW_CTX_TASK_ID='scrapping_data' AIRFLOW_CTX_EXECUTION_DATE='2025-03-01T08:55:16.382449+00:00' AIRFLOW_CTX_TRY_NUMBER='1' AIRFLOW_CTX_DAG_RUN_ID='manual__2025-03-01T08:55:16.382449+00:00'
[2025-03-01T08:55:23.908+0000] {logging_mixin.py:190} INFO - Task instance is in running state
[2025-03-01T08:55:23.909+0000] {logging_mixin.py:190} INFO -  Previous state of the Task instance: queued
[2025-03-01T08:55:23.909+0000] {logging_mixin.py:190} INFO - Current task name:scrapping_data state:running start_date:2025-03-01 08:55:23.687920+00:00
[2025-03-01T08:55:23.910+0000] {logging_mixin.py:190} INFO - Dag name:etl_scrapper_pipeline and current dag run status:running
[2025-03-01T08:55:23.910+0000] {taskinstance.py:732} INFO - ::endgroup::
[2025-03-01T08:55:23.913+0000] {taskinstance.py:3313} ERROR - Task failed with exception
Traceback (most recent call last):
  File "/home/airflow/.local/lib/python3.12/site-packages/selenium/webdriver/common/driver_finder.py", line 64, in _binary_paths
    raise ValueError(f"The path is not a valid file: {path}")
ValueError: The path is not a valid file: chromedriver.exe

The above exception was the direct cause of the following exception:

Traceback (most recent call last):
  File "/home/airflow/.local/lib/python3.12/site-packages/airflow/models/taskinstance.py", line 768, in _execute_task
    result = _execute_callable(context=context, **execute_callable_kwargs)
             ^^^^^^^^^^^^^^^^^^^^^^^^^^^^^^^^^^^^^^^^^^^^^^^^^^^^^^^^^^^^^
  File "/home/airflow/.local/lib/python3.12/site-packages/airflow/models/taskinstance.py", line 734, in _execute_callable
    return ExecutionCallableRunner(
           ^^^^^^^^^^^^^^^^^^^^^^^^
  File "/home/airflow/.local/lib/python3.12/site-packages/airflow/utils/operator_helpers.py", line 252, in run
    return self.func(*args, **kwargs)
           ^^^^^^^^^^^^^^^^^^^^^^^^^^
  File "/home/airflow/.local/lib/python3.12/site-packages/airflow/models/baseoperator.py", line 424, in wrapper
    return func(self, *args, **kwargs)
           ^^^^^^^^^^^^^^^^^^^^^^^^^^^
  File "/home/airflow/.local/lib/python3.12/site-packages/airflow/operators/python.py", line 238, in execute
    return_value = self.execute_callable()
                   ^^^^^^^^^^^^^^^^^^^^^^^
  File "/home/airflow/.local/lib/python3.12/site-packages/airflow/operators/python.py", line 256, in execute_callable
    return runner.run(*self.op_args, **self.op_kwargs)
           ^^^^^^^^^^^^^^^^^^^^^^^^^^^^^^^^^^^^^^^^^^^
  File "/home/airflow/.local/lib/python3.12/site-packages/airflow/utils/operator_helpers.py", line 252, in run
    return self.func(*args, **kwargs)
           ^^^^^^^^^^^^^^^^^^^^^^^^^^
  File "/opt/airflow/dags/etl_dags.py", line 37, in extract_file
    driver = webdriver.Chrome(service=service, options=options)
             ^^^^^^^^^^^^^^^^^^^^^^^^^^^^^^^^^^^^^^^^^^^^^^^^^^
  File "/home/airflow/.local/lib/python3.12/site-packages/selenium/webdriver/chrome/webdriver.py", line 45, in __init__
    super().__init__(
  File "/home/airflow/.local/lib/python3.12/site-packages/selenium/webdriver/chromium/webdriver.py", line 50, in __init__
    if finder.get_browser_path():
       ^^^^^^^^^^^^^^^^^^^^^^^^^
  File "/home/airflow/.local/lib/python3.12/site-packages/selenium/webdriver/common/driver_finder.py", line 47, in get_browser_path
    return self._binary_paths()["browser_path"]
           ^^^^^^^^^^^^^^^^^^^^
  File "/home/airflow/.local/lib/python3.12/site-packages/selenium/webdriver/common/driver_finder.py", line 78, in _binary_paths
    raise NoSuchDriverException(msg) from err
selenium.common.exceptions.NoSuchDriverException: Message: Unable to obtain driver for chrome; For documentation on this error, please visit: https://www.selenium.dev/documentation/webdriver/troubleshooting/errors/driver_location

[2025-03-01T08:55:23.936+0000] {logging_mixin.py:190} INFO - Task instance in failure state
[2025-03-01T08:55:23.937+0000] {logging_mixin.py:190} INFO - Task start:2025-03-01 08:55:23.687920+00:00 end:2025-03-01 08:55:23.935878+00:00 duration:0.247958
[2025-03-01T08:55:23.938+0000] {logging_mixin.py:190} INFO - Task:<Task(PythonOperator): scrapping_data> dag:<DAG: etl_scrapper_pipeline> dagrun:<DagRun etl_scrapper_pipeline @ 2025-03-01 08:55:16.382449+00:00: manual__2025-03-01T08:55:16.382449+00:00, state:running, queued_at: 2025-03-01 08:55:16.413488+00:00. externally triggered: True>
[2025-03-01T08:55:23.938+0000] {logging_mixin.py:190} INFO - Failure caused by Message: Unable to obtain driver for chrome; For documentation on this error, please visit: https://www.selenium.dev/documentation/webdriver/troubleshooting/errors/driver_location
[2025-03-01T08:55:23.938+0000] {taskinstance.py:1226} INFO - Marking task as UP_FOR_RETRY. dag_id=etl_scrapper_pipeline, task_id=scrapping_data, run_id=manual__2025-03-01T08:55:16.382449+00:00, execution_date=20250301T085516, start_date=20250301T085523, end_date=20250301T085523
[2025-03-01T08:55:23.977+0000] {taskinstance.py:341} INFO - ::group::Post task execution logs
[2025-03-01T08:55:23.978+0000] {standard_task_runner.py:124} ERROR - Failed to execute job 150 for task scrapping_data (Message: Unable to obtain driver for chrome; For documentation on this error, please visit: https://www.selenium.dev/documentation/webdriver/troubleshooting/errors/driver_location
; 129)
Traceback (most recent call last):
  File "/home/airflow/.local/lib/python3.12/site-packages/selenium/webdriver/common/driver_finder.py", line 64, in _binary_paths
    raise ValueError(f"The path is not a valid file: {path}")
ValueError: The path is not a valid file: chromedriver.exe

The above exception was the direct cause of the following exception:

Traceback (most recent call last):
  File "/home/airflow/.local/lib/python3.12/site-packages/airflow/task/task_runner/standard_task_runner.py", line 117, in _start_by_fork
    ret = args.func(args, dag=self.dag)
          ^^^^^^^^^^^^^^^^^^^^^^^^^^^^^
  File "/home/airflow/.local/lib/python3.12/site-packages/airflow/cli/cli_config.py", line 49, in command
    return func(*args, **kwargs)
           ^^^^^^^^^^^^^^^^^^^^^
  File "/home/airflow/.local/lib/python3.12/site-packages/airflow/utils/cli.py", line 116, in wrapper
    return f(*args, **kwargs)
           ^^^^^^^^^^^^^^^^^^
  File "/home/airflow/.local/lib/python3.12/site-packages/airflow/cli/commands/task_command.py", line 483, in task_run
    task_return_code = _run_task_by_selected_method(args, _dag, ti)
                       ^^^^^^^^^^^^^^^^^^^^^^^^^^^^^^^^^^^^^^^^^^^^
  File "/home/airflow/.local/lib/python3.12/site-packages/airflow/cli/commands/task_command.py", line 256, in _run_task_by_selected_method
    return _run_raw_task(args, ti)
           ^^^^^^^^^^^^^^^^^^^^^^^
  File "/home/airflow/.local/lib/python3.12/site-packages/airflow/cli/commands/task_command.py", line 341, in _run_raw_task
    return ti._run_raw_task(
           ^^^^^^^^^^^^^^^^^
  File "/home/airflow/.local/lib/python3.12/site-packages/airflow/utils/session.py", line 97, in wrapper
    return func(*args, session=session, **kwargs)
           ^^^^^^^^^^^^^^^^^^^^^^^^^^^^^^^^^^^^^^
  File "/home/airflow/.local/lib/python3.12/site-packages/airflow/models/taskinstance.py", line 3006, in _run_raw_task
    return _run_raw_task(
           ^^^^^^^^^^^^^^
  File "/home/airflow/.local/lib/python3.12/site-packages/airflow/models/taskinstance.py", line 274, in _run_raw_task
    TaskInstance._execute_task_with_callbacks(
  File "/home/airflow/.local/lib/python3.12/site-packages/airflow/models/taskinstance.py", line 3161, in _execute_task_with_callbacks
    result = self._execute_task(context, task_orig)
             ^^^^^^^^^^^^^^^^^^^^^^^^^^^^^^^^^^^^^^
  File "/home/airflow/.local/lib/python3.12/site-packages/airflow/models/taskinstance.py", line 3185, in _execute_task
    return _execute_task(self, context, task_orig)
           ^^^^^^^^^^^^^^^^^^^^^^^^^^^^^^^^^^^^^^^
  File "/home/airflow/.local/lib/python3.12/site-packages/airflow/models/taskinstance.py", line 768, in _execute_task
    result = _execute_callable(context=context, **execute_callable_kwargs)
             ^^^^^^^^^^^^^^^^^^^^^^^^^^^^^^^^^^^^^^^^^^^^^^^^^^^^^^^^^^^^^
  File "/home/airflow/.local/lib/python3.12/site-packages/airflow/models/taskinstance.py", line 734, in _execute_callable
    return ExecutionCallableRunner(
           ^^^^^^^^^^^^^^^^^^^^^^^^
  File "/home/airflow/.local/lib/python3.12/site-packages/airflow/utils/operator_helpers.py", line 252, in run
    return self.func(*args, **kwargs)
           ^^^^^^^^^^^^^^^^^^^^^^^^^^
  File "/home/airflow/.local/lib/python3.12/site-packages/airflow/models/baseoperator.py", line 424, in wrapper
    return func(self, *args, **kwargs)
           ^^^^^^^^^^^^^^^^^^^^^^^^^^^
  File "/home/airflow/.local/lib/python3.12/site-packages/airflow/operators/python.py", line 238, in execute
    return_value = self.execute_callable()
                   ^^^^^^^^^^^^^^^^^^^^^^^
  File "/home/airflow/.local/lib/python3.12/site-packages/airflow/operators/python.py", line 256, in execute_callable
    return runner.run(*self.op_args, **self.op_kwargs)
           ^^^^^^^^^^^^^^^^^^^^^^^^^^^^^^^^^^^^^^^^^^^
  File "/home/airflow/.local/lib/python3.12/site-packages/airflow/utils/operator_helpers.py", line 252, in run
    return self.func(*args, **kwargs)
           ^^^^^^^^^^^^^^^^^^^^^^^^^^
  File "/opt/airflow/dags/etl_dags.py", line 37, in extract_file
    driver = webdriver.Chrome(service=service, options=options)
             ^^^^^^^^^^^^^^^^^^^^^^^^^^^^^^^^^^^^^^^^^^^^^^^^^^
  File "/home/airflow/.local/lib/python3.12/site-packages/selenium/webdriver/chrome/webdriver.py", line 45, in __init__
    super().__init__(
  File "/home/airflow/.local/lib/python3.12/site-packages/selenium/webdriver/chromium/webdriver.py", line 50, in __init__
    if finder.get_browser_path():
       ^^^^^^^^^^^^^^^^^^^^^^^^^
  File "/home/airflow/.local/lib/python3.12/site-packages/selenium/webdriver/common/driver_finder.py", line 47, in get_browser_path
    return self._binary_paths()["browser_path"]
           ^^^^^^^^^^^^^^^^^^^^
  File "/home/airflow/.local/lib/python3.12/site-packages/selenium/webdriver/common/driver_finder.py", line 78, in _binary_paths
    raise NoSuchDriverException(msg) from err
selenium.common.exceptions.NoSuchDriverException: Message: Unable to obtain driver for chrome; For documentation on this error, please visit: https://www.selenium.dev/documentation/webdriver/troubleshooting/errors/driver_location

[2025-03-01T08:55:24.003+0000] {local_task_job_runner.py:266} INFO - Task exited with return code 1
[2025-03-01T08:55:24.033+0000] {taskinstance.py:3901} INFO - 0 downstream tasks scheduled from follow-on schedule check
[2025-03-01T08:55:24.035+0000] {local_task_job_runner.py:245} INFO - ::endgroup::
