[2025-02-28T15:44:50.489+0000] {local_task_job_runner.py:123} INFO - ::group::Pre task execution logs
[2025-02-28T15:44:50.516+0000] {taskinstance.py:2614} INFO - Dependencies all met for dep_context=non-requeueable deps ti=<TaskInstance: etl_scrapper_pipeline.check_raw_file manual__2025-02-28T15:33:16.089080+00:00 [queued]>
[2025-02-28T15:44:50.528+0000] {taskinstance.py:2614} INFO - Dependencies all met for dep_context=requeueable deps ti=<TaskInstance: etl_scrapper_pipeline.check_raw_file manual__2025-02-28T15:33:16.089080+00:00 [queued]>
[2025-02-28T15:44:50.530+0000] {taskinstance.py:2867} INFO - Starting attempt 6 of 6
[2025-02-28T15:44:50.546+0000] {taskinstance.py:2890} INFO - Executing <Task(FileSensor): check_raw_file> on 2025-02-28 15:33:16.089080+00:00
[2025-02-28T15:44:50.557+0000] {warnings.py:112} WARNING - /home/***/.local/lib/python3.12/site-packages/***/task/task_runner/standard_task_runner.py:70: DeprecationWarning: This process (pid=343) is multi-threaded, use of fork() may lead to deadlocks in the child.
  pid = os.fork()

[2025-02-28T15:44:50.559+0000] {standard_task_runner.py:72} INFO - Started process 345 to run task
[2025-02-28T15:44:50.559+0000] {standard_task_runner.py:104} INFO - Running: ['***', 'tasks', 'run', 'etl_scrapper_pipeline', 'check_raw_file', 'manual__2025-02-28T15:33:16.089080+00:00', '--job-id', '27', '--raw', '--subdir', 'DAGS_FOLDER/etl_dags.py', '--cfg-path', '/tmp/tmp56qe_2yu']
[2025-02-28T15:44:50.560+0000] {standard_task_runner.py:105} INFO - Job 27: Subtask check_raw_file
[2025-02-28T15:44:50.619+0000] {task_command.py:467} INFO - Running <TaskInstance: etl_scrapper_pipeline.check_raw_file manual__2025-02-28T15:33:16.089080+00:00 [running]> on host 081ded626b25
[2025-02-28T15:44:50.706+0000] {taskinstance.py:3134} INFO - Exporting env vars: AIRFLOW_CTX_DAG_OWNER='***' AIRFLOW_CTX_DAG_ID='etl_scrapper_pipeline' AIRFLOW_CTX_TASK_ID='check_raw_file' AIRFLOW_CTX_EXECUTION_DATE='2025-02-28T15:33:16.089080+00:00' AIRFLOW_CTX_TRY_NUMBER='6' AIRFLOW_CTX_DAG_RUN_ID='manual__2025-02-28T15:33:16.089080+00:00'
[2025-02-28T15:44:50.708+0000] {logging_mixin.py:190} INFO - Task instance is in running state
[2025-02-28T15:44:50.708+0000] {logging_mixin.py:190} INFO -  Previous state of the Task instance: queued
[2025-02-28T15:44:50.708+0000] {logging_mixin.py:190} INFO - Current task name:check_raw_file state:running start_date:2025-02-28 15:44:50.517637+00:00
[2025-02-28T15:44:50.709+0000] {logging_mixin.py:190} INFO - Dag name:etl_scrapper_pipeline and current dag run status:running
[2025-02-28T15:44:50.710+0000] {taskinstance.py:732} INFO - ::endgroup::
[2025-02-28T15:44:50.710+0000] {baseoperator.py:423} WARNING - FileSensor.execute cannot be called outside TaskInstance!
[2025-02-28T15:44:50.730+0000] {taskinstance.py:3313} ERROR - Task failed with exception
Traceback (most recent call last):
  File "/home/airflow/.local/lib/python3.12/site-packages/airflow/models/taskinstance.py", line 768, in _execute_task
    result = _execute_callable(context=context, **execute_callable_kwargs)
             ^^^^^^^^^^^^^^^^^^^^^^^^^^^^^^^^^^^^^^^^^^^^^^^^^^^^^^^^^^^^^
  File "/home/airflow/.local/lib/python3.12/site-packages/airflow/models/taskinstance.py", line 734, in _execute_callable
    return ExecutionCallableRunner(
           ^^^^^^^^^^^^^^^^^^^^^^^^
  File "/home/airflow/.local/lib/python3.12/site-packages/airflow/utils/operator_helpers.py", line 252, in run
    return self.func(*args, **kwargs)
           ^^^^^^^^^^^^^^^^^^^^^^^^^^
  File "/home/airflow/.local/lib/python3.12/site-packages/airflow/models/baseoperator.py", line 424, in wrapper
    return func(self, *args, **kwargs)
           ^^^^^^^^^^^^^^^^^^^^^^^^^^^
  File "/home/airflow/.local/lib/python3.12/site-packages/airflow/sensors/filesystem.py", line 123, in execute
    super().execute(context=context)
  File "/home/airflow/.local/lib/python3.12/site-packages/airflow/models/baseoperator.py", line 424, in wrapper
    return func(self, *args, **kwargs)
           ^^^^^^^^^^^^^^^^^^^^^^^^^^^
  File "/home/airflow/.local/lib/python3.12/site-packages/airflow/sensors/base.py", line 309, in execute
    raise e
  File "/home/airflow/.local/lib/python3.12/site-packages/airflow/sensors/base.py", line 289, in execute
    poke_return = self.poke(context)
                  ^^^^^^^^^^^^^^^^^^
  File "/home/airflow/.local/lib/python3.12/site-packages/airflow/sensors/filesystem.py", line 109, in poke
    self.log.info("Poking for file %s", self.path)
                                        ^^^^^^^^^
  File "/usr/local/lib/python3.12/functools.py", line 998, in __get__
    val = self.func(instance)
          ^^^^^^^^^^^^^^^^^^^
  File "/home/airflow/.local/lib/python3.12/site-packages/airflow/sensors/filesystem.py", line 103, in path
    hook = FSHook(self.fs_conn_id)
           ^^^^^^^^^^^^^^^^^^^^^^^
  File "/home/airflow/.local/lib/python3.12/site-packages/airflow/hooks/filesystem.py", line 64, in __init__
    conn = self.get_connection(fs_conn_id)
           ^^^^^^^^^^^^^^^^^^^^^^^^^^^^^^^
  File "/home/airflow/.local/lib/python3.12/site-packages/airflow/hooks/base.py", line 83, in get_connection
    conn = Connection.get_connection_from_secrets(conn_id)
           ^^^^^^^^^^^^^^^^^^^^^^^^^^^^^^^^^^^^^^^^^^^^^^^
  File "/home/airflow/.local/lib/python3.12/site-packages/airflow/models/connection.py", line 537, in get_connection_from_secrets
    raise AirflowNotFoundException(f"The conn_id `{conn_id}` isn't defined")
airflow.exceptions.AirflowNotFoundException: The conn_id `fs_default` isn't defined
[2025-02-28T15:44:50.736+0000] {logging_mixin.py:190} INFO - Task instance in failure state
[2025-02-28T15:44:50.737+0000] {logging_mixin.py:190} INFO - Task start:2025-02-28 15:44:50.517637+00:00 end:2025-02-28 15:44:50.735781+00:00 duration:0.218144
[2025-02-28T15:44:50.738+0000] {logging_mixin.py:190} INFO - Task:<Task(FileSensor): check_raw_file> dag:<DAG: etl_scrapper_pipeline> dagrun:<DagRun etl_scrapper_pipeline @ 2025-02-28 15:33:16.089080+00:00: manual__2025-02-28T15:33:16.089080+00:00, state:running, queued_at: 2025-02-28 15:38:57.479679+00:00. externally triggered: True>
[2025-02-28T15:44:50.738+0000] {logging_mixin.py:190} INFO - Failure caused by The conn_id `fs_default` isn't defined
[2025-02-28T15:44:50.739+0000] {taskinstance.py:1226} INFO - Marking task as FAILED. dag_id=etl_scrapper_pipeline, task_id=check_raw_file, run_id=manual__2025-02-28T15:33:16.089080+00:00, execution_date=20250228T153316, start_date=20250228T154450, end_date=20250228T154450
[2025-02-28T15:44:50.768+0000] {taskinstance.py:341} INFO - ::group::Post task execution logs
[2025-02-28T15:44:50.769+0000] {standard_task_runner.py:124} ERROR - Failed to execute job 27 for task check_raw_file (The conn_id `fs_default` isn't defined; 345)
Traceback (most recent call last):
  File "/home/airflow/.local/lib/python3.12/site-packages/airflow/task/task_runner/standard_task_runner.py", line 117, in _start_by_fork
    ret = args.func(args, dag=self.dag)
          ^^^^^^^^^^^^^^^^^^^^^^^^^^^^^
  File "/home/airflow/.local/lib/python3.12/site-packages/airflow/cli/cli_config.py", line 49, in command
    return func(*args, **kwargs)
           ^^^^^^^^^^^^^^^^^^^^^
  File "/home/airflow/.local/lib/python3.12/site-packages/airflow/utils/cli.py", line 116, in wrapper
    return f(*args, **kwargs)
           ^^^^^^^^^^^^^^^^^^
  File "/home/airflow/.local/lib/python3.12/site-packages/airflow/cli/commands/task_command.py", line 483, in task_run
    task_return_code = _run_task_by_selected_method(args, _dag, ti)
                       ^^^^^^^^^^^^^^^^^^^^^^^^^^^^^^^^^^^^^^^^^^^^
  File "/home/airflow/.local/lib/python3.12/site-packages/airflow/cli/commands/task_command.py", line 256, in _run_task_by_selected_method
    return _run_raw_task(args, ti)
           ^^^^^^^^^^^^^^^^^^^^^^^
  File "/home/airflow/.local/lib/python3.12/site-packages/airflow/cli/commands/task_command.py", line 341, in _run_raw_task
    return ti._run_raw_task(
           ^^^^^^^^^^^^^^^^^
  File "/home/airflow/.local/lib/python3.12/site-packages/airflow/utils/session.py", line 97, in wrapper
    return func(*args, session=session, **kwargs)
           ^^^^^^^^^^^^^^^^^^^^^^^^^^^^^^^^^^^^^^
  File "/home/airflow/.local/lib/python3.12/site-packages/airflow/models/taskinstance.py", line 3006, in _run_raw_task
    return _run_raw_task(
           ^^^^^^^^^^^^^^
  File "/home/airflow/.local/lib/python3.12/site-packages/airflow/models/taskinstance.py", line 274, in _run_raw_task
    TaskInstance._execute_task_with_callbacks(
  File "/home/airflow/.local/lib/python3.12/site-packages/airflow/models/taskinstance.py", line 3161, in _execute_task_with_callbacks
    result = self._execute_task(context, task_orig)
             ^^^^^^^^^^^^^^^^^^^^^^^^^^^^^^^^^^^^^^
  File "/home/airflow/.local/lib/python3.12/site-packages/airflow/models/taskinstance.py", line 3185, in _execute_task
    return _execute_task(self, context, task_orig)
           ^^^^^^^^^^^^^^^^^^^^^^^^^^^^^^^^^^^^^^^
  File "/home/airflow/.local/lib/python3.12/site-packages/airflow/models/taskinstance.py", line 768, in _execute_task
    result = _execute_callable(context=context, **execute_callable_kwargs)
             ^^^^^^^^^^^^^^^^^^^^^^^^^^^^^^^^^^^^^^^^^^^^^^^^^^^^^^^^^^^^^
  File "/home/airflow/.local/lib/python3.12/site-packages/airflow/models/taskinstance.py", line 734, in _execute_callable
    return ExecutionCallableRunner(
           ^^^^^^^^^^^^^^^^^^^^^^^^
  File "/home/airflow/.local/lib/python3.12/site-packages/airflow/utils/operator_helpers.py", line 252, in run
    return self.func(*args, **kwargs)
           ^^^^^^^^^^^^^^^^^^^^^^^^^^
  File "/home/airflow/.local/lib/python3.12/site-packages/airflow/models/baseoperator.py", line 424, in wrapper
    return func(self, *args, **kwargs)
           ^^^^^^^^^^^^^^^^^^^^^^^^^^^
  File "/home/airflow/.local/lib/python3.12/site-packages/airflow/sensors/filesystem.py", line 123, in execute
    super().execute(context=context)
  File "/home/airflow/.local/lib/python3.12/site-packages/airflow/models/baseoperator.py", line 424, in wrapper
    return func(self, *args, **kwargs)
           ^^^^^^^^^^^^^^^^^^^^^^^^^^^
  File "/home/airflow/.local/lib/python3.12/site-packages/airflow/sensors/base.py", line 309, in execute
    raise e
  File "/home/airflow/.local/lib/python3.12/site-packages/airflow/sensors/base.py", line 289, in execute
    poke_return = self.poke(context)
                  ^^^^^^^^^^^^^^^^^^
  File "/home/airflow/.local/lib/python3.12/site-packages/airflow/sensors/filesystem.py", line 109, in poke
    self.log.info("Poking for file %s", self.path)
                                        ^^^^^^^^^
  File "/usr/local/lib/python3.12/functools.py", line 998, in __get__
    val = self.func(instance)
          ^^^^^^^^^^^^^^^^^^^
  File "/home/airflow/.local/lib/python3.12/site-packages/airflow/sensors/filesystem.py", line 103, in path
    hook = FSHook(self.fs_conn_id)
           ^^^^^^^^^^^^^^^^^^^^^^^
  File "/home/airflow/.local/lib/python3.12/site-packages/airflow/hooks/filesystem.py", line 64, in __init__
    conn = self.get_connection(fs_conn_id)
           ^^^^^^^^^^^^^^^^^^^^^^^^^^^^^^^
  File "/home/airflow/.local/lib/python3.12/site-packages/airflow/hooks/base.py", line 83, in get_connection
    conn = Connection.get_connection_from_secrets(conn_id)
           ^^^^^^^^^^^^^^^^^^^^^^^^^^^^^^^^^^^^^^^^^^^^^^^
  File "/home/airflow/.local/lib/python3.12/site-packages/airflow/models/connection.py", line 537, in get_connection_from_secrets
    raise AirflowNotFoundException(f"The conn_id `{conn_id}` isn't defined")
airflow.exceptions.AirflowNotFoundException: The conn_id `fs_default` isn't defined
[2025-02-28T15:44:50.815+0000] {local_task_job_runner.py:266} INFO - Task exited with return code 1
[2025-02-28T15:44:50.847+0000] {taskinstance.py:3901} INFO - 0 downstream tasks scheduled from follow-on schedule check
[2025-02-28T15:44:50.852+0000] {local_task_job_runner.py:245} INFO - ::endgroup::
