[2025-03-01T09:08:47.609+0000] {local_task_job_runner.py:123} INFO - ::group::Pre task execution logs
[2025-03-01T09:08:47.653+0000] {taskinstance.py:2614} INFO - Dependencies all met for dep_context=non-requeueable deps ti=<TaskInstance: etl_scrapper_pipeline.check_raw_file manual__2025-03-01T09:07:42.417433+00:00 [queued]>
[2025-03-01T09:08:47.667+0000] {taskinstance.py:2614} INFO - Dependencies all met for dep_context=requeueable deps ti=<TaskInstance: etl_scrapper_pipeline.check_raw_file manual__2025-03-01T09:07:42.417433+00:00 [queued]>
[2025-03-01T09:08:47.668+0000] {taskinstance.py:2867} INFO - Starting attempt 1 of 2
[2025-03-01T09:08:47.685+0000] {taskinstance.py:2890} INFO - Executing <Task(FileSensor): check_raw_file> on 2025-03-01 09:07:42.417433+00:00
[2025-03-01T09:08:47.698+0000] {warnings.py:112} WARNING - /home/***/.local/lib/python3.12/site-packages/***/task/task_runner/standard_task_runner.py:70: DeprecationWarning: This process (pid=103) is multi-threaded, use of fork() may lead to deadlocks in the child.
  pid = os.fork()

[2025-03-01T09:08:47.699+0000] {standard_task_runner.py:104} INFO - Running: ['***', 'tasks', 'run', 'etl_scrapper_pipeline', 'check_raw_file', 'manual__2025-03-01T09:07:42.417433+00:00', '--job-id', '187', '--raw', '--subdir', 'DAGS_FOLDER/etl_dags.py', '--cfg-path', '/tmp/tmp9ppcfap3']
[2025-03-01T09:08:47.700+0000] {standard_task_runner.py:72} INFO - Started process 106 to run task
[2025-03-01T09:08:47.700+0000] {standard_task_runner.py:105} INFO - Job 187: Subtask check_raw_file
[2025-03-01T09:08:47.756+0000] {task_command.py:467} INFO - Running <TaskInstance: etl_scrapper_pipeline.check_raw_file manual__2025-03-01T09:07:42.417433+00:00 [running]> on host 18f96a44278a
[2025-03-01T09:08:47.854+0000] {taskinstance.py:3134} INFO - Exporting env vars: AIRFLOW_CTX_DAG_OWNER='***' AIRFLOW_CTX_DAG_ID='etl_scrapper_pipeline' AIRFLOW_CTX_TASK_ID='check_raw_file' AIRFLOW_CTX_EXECUTION_DATE='2025-03-01T09:07:42.417433+00:00' AIRFLOW_CTX_TRY_NUMBER='1' AIRFLOW_CTX_DAG_RUN_ID='manual__2025-03-01T09:07:42.417433+00:00'
[2025-03-01T09:08:47.857+0000] {logging_mixin.py:190} INFO - Task instance is in running state
[2025-03-01T09:08:47.857+0000] {logging_mixin.py:190} INFO -  Previous state of the Task instance: queued
[2025-03-01T09:08:47.858+0000] {logging_mixin.py:190} INFO - Current task name:check_raw_file state:running start_date:2025-03-01 09:08:47.655162+00:00
[2025-03-01T09:08:47.858+0000] {logging_mixin.py:190} INFO - Dag name:etl_scrapper_pipeline and current dag run status:running
[2025-03-01T09:08:47.859+0000] {taskinstance.py:732} INFO - ::endgroup::
[2025-03-01T09:08:47.860+0000] {baseoperator.py:423} WARNING - FileSensor.execute cannot be called outside TaskInstance!
[2025-03-01T09:08:47.872+0000] {base.py:84} INFO - Retrieving connection 'fs_default'
[2025-03-01T09:08:47.873+0000] {filesystem.py:109} INFO - Poking for file /raw_data.csv
[2025-03-01T09:08:57.876+0000] {filesystem.py:109} INFO - Poking for file /raw_data.csv
[2025-03-01T09:09:07.877+0000] {filesystem.py:109} INFO - Poking for file /raw_data.csv
[2025-03-01T09:09:17.877+0000] {filesystem.py:109} INFO - Poking for file /raw_data.csv
[2025-03-01T09:09:27.878+0000] {filesystem.py:109} INFO - Poking for file /raw_data.csv
[2025-03-01T09:09:37.880+0000] {filesystem.py:109} INFO - Poking for file /raw_data.csv
[2025-03-01T09:09:47.880+0000] {filesystem.py:109} INFO - Poking for file /raw_data.csv
[2025-03-01T09:09:57.881+0000] {filesystem.py:109} INFO - Poking for file /raw_data.csv
[2025-03-01T09:10:07.883+0000] {filesystem.py:109} INFO - Poking for file /raw_data.csv
[2025-03-01T09:10:17.883+0000] {filesystem.py:109} INFO - Poking for file /raw_data.csv
[2025-03-01T09:10:27.884+0000] {filesystem.py:109} INFO - Poking for file /raw_data.csv
[2025-03-01T09:10:37.885+0000] {filesystem.py:109} INFO - Poking for file /raw_data.csv
[2025-03-01T09:10:47.885+0000] {filesystem.py:109} INFO - Poking for file /raw_data.csv
[2025-03-01T09:10:57.887+0000] {filesystem.py:109} INFO - Poking for file /raw_data.csv
[2025-03-01T09:11:07.888+0000] {filesystem.py:109} INFO - Poking for file /raw_data.csv
[2025-03-01T09:11:17.888+0000] {filesystem.py:109} INFO - Poking for file /raw_data.csv
[2025-03-01T09:11:27.890+0000] {filesystem.py:109} INFO - Poking for file /raw_data.csv
[2025-03-01T09:11:37.891+0000] {filesystem.py:109} INFO - Poking for file /raw_data.csv
[2025-03-01T09:11:47.891+0000] {filesystem.py:109} INFO - Poking for file /raw_data.csv
[2025-03-01T09:11:57.892+0000] {filesystem.py:109} INFO - Poking for file /raw_data.csv
[2025-03-01T09:12:07.893+0000] {filesystem.py:109} INFO - Poking for file /raw_data.csv
[2025-03-01T09:12:17.893+0000] {filesystem.py:109} INFO - Poking for file /raw_data.csv
[2025-03-01T09:12:27.894+0000] {filesystem.py:109} INFO - Poking for file /raw_data.csv
[2025-03-01T09:12:37.895+0000] {filesystem.py:109} INFO - Poking for file /raw_data.csv
[2025-03-01T09:12:47.895+0000] {filesystem.py:109} INFO - Poking for file /raw_data.csv
[2025-03-01T09:12:57.896+0000] {filesystem.py:109} INFO - Poking for file /raw_data.csv
[2025-03-01T09:13:07.897+0000] {filesystem.py:109} INFO - Poking for file /raw_data.csv
[2025-03-01T09:13:17.897+0000] {filesystem.py:109} INFO - Poking for file /raw_data.csv
[2025-03-01T09:13:27.898+0000] {filesystem.py:109} INFO - Poking for file /raw_data.csv
[2025-03-01T09:13:37.899+0000] {filesystem.py:109} INFO - Poking for file /raw_data.csv
[2025-03-01T09:13:47.899+0000] {filesystem.py:109} INFO - Poking for file /raw_data.csv
[2025-03-01T09:13:47.900+0000] {taskinstance.py:3313} ERROR - Task failed with exception
Traceback (most recent call last):
  File "/home/airflow/.local/lib/python3.12/site-packages/airflow/models/taskinstance.py", line 768, in _execute_task
    result = _execute_callable(context=context, **execute_callable_kwargs)
             ^^^^^^^^^^^^^^^^^^^^^^^^^^^^^^^^^^^^^^^^^^^^^^^^^^^^^^^^^^^^^
  File "/home/airflow/.local/lib/python3.12/site-packages/airflow/models/taskinstance.py", line 734, in _execute_callable
    return ExecutionCallableRunner(
           ^^^^^^^^^^^^^^^^^^^^^^^^
  File "/home/airflow/.local/lib/python3.12/site-packages/airflow/utils/operator_helpers.py", line 252, in run
    return self.func(*args, **kwargs)
           ^^^^^^^^^^^^^^^^^^^^^^^^^^
  File "/home/airflow/.local/lib/python3.12/site-packages/airflow/models/baseoperator.py", line 424, in wrapper
    return func(self, *args, **kwargs)
           ^^^^^^^^^^^^^^^^^^^^^^^^^^^
  File "/home/airflow/.local/lib/python3.12/site-packages/airflow/sensors/filesystem.py", line 123, in execute
    super().execute(context=context)
  File "/home/airflow/.local/lib/python3.12/site-packages/airflow/models/baseoperator.py", line 424, in wrapper
    return func(self, *args, **kwargs)
           ^^^^^^^^^^^^^^^^^^^^^^^^^^^
  File "/home/airflow/.local/lib/python3.12/site-packages/airflow/sensors/base.py", line 326, in execute
    raise AirflowSensorTimeout(message)
airflow.exceptions.AirflowSensorTimeout: Sensor has timed out; run duration of 300.05189934699956 seconds exceeds the specified timeout of 300.0.
[2025-03-01T09:13:47.912+0000] {logging_mixin.py:190} INFO - Task instance in failure state
[2025-03-01T09:13:47.913+0000] {logging_mixin.py:190} INFO - Task start:2025-03-01 09:08:47.655162+00:00 end:2025-03-01 09:13:47.912305+00:00 duration:300.257143
[2025-03-01T09:13:47.914+0000] {logging_mixin.py:190} INFO - Task:<Task(FileSensor): check_raw_file> dag:<DAG: etl_scrapper_pipeline> dagrun:<DagRun etl_scrapper_pipeline @ 2025-03-01 09:07:42.417433+00:00: manual__2025-03-01T09:07:42.417433+00:00, state:running, queued_at: 2025-03-01 09:07:42.443119+00:00. externally triggered: True>
[2025-03-01T09:13:47.915+0000] {logging_mixin.py:190} INFO - Failure caused by Sensor has timed out; run duration of 300.05189934699956 seconds exceeds the specified timeout of 300.0.
[2025-03-01T09:13:47.915+0000] {taskinstance.py:1226} INFO - Immediate failure requested. Marking task as FAILED. dag_id=etl_scrapper_pipeline, task_id=check_raw_file, run_id=manual__2025-03-01T09:07:42.417433+00:00, execution_date=20250301T090742, start_date=20250301T090847, end_date=20250301T091347
[2025-03-01T09:13:47.950+0000] {taskinstance.py:341} INFO - ::group::Post task execution logs
[2025-03-01T09:13:47.951+0000] {standard_task_runner.py:124} ERROR - Failed to execute job 187 for task check_raw_file (Sensor has timed out; run duration of 300.05189934699956 seconds exceeds the specified timeout of 300.0.; 106)
Traceback (most recent call last):
  File "/home/airflow/.local/lib/python3.12/site-packages/airflow/task/task_runner/standard_task_runner.py", line 117, in _start_by_fork
    ret = args.func(args, dag=self.dag)
          ^^^^^^^^^^^^^^^^^^^^^^^^^^^^^
  File "/home/airflow/.local/lib/python3.12/site-packages/airflow/cli/cli_config.py", line 49, in command
    return func(*args, **kwargs)
           ^^^^^^^^^^^^^^^^^^^^^
  File "/home/airflow/.local/lib/python3.12/site-packages/airflow/utils/cli.py", line 116, in wrapper
    return f(*args, **kwargs)
           ^^^^^^^^^^^^^^^^^^
  File "/home/airflow/.local/lib/python3.12/site-packages/airflow/cli/commands/task_command.py", line 483, in task_run
    task_return_code = _run_task_by_selected_method(args, _dag, ti)
                       ^^^^^^^^^^^^^^^^^^^^^^^^^^^^^^^^^^^^^^^^^^^^
  File "/home/airflow/.local/lib/python3.12/site-packages/airflow/cli/commands/task_command.py", line 256, in _run_task_by_selected_method
    return _run_raw_task(args, ti)
           ^^^^^^^^^^^^^^^^^^^^^^^
  File "/home/airflow/.local/lib/python3.12/site-packages/airflow/cli/commands/task_command.py", line 341, in _run_raw_task
    return ti._run_raw_task(
           ^^^^^^^^^^^^^^^^^
  File "/home/airflow/.local/lib/python3.12/site-packages/airflow/utils/session.py", line 97, in wrapper
    return func(*args, session=session, **kwargs)
           ^^^^^^^^^^^^^^^^^^^^^^^^^^^^^^^^^^^^^^
  File "/home/airflow/.local/lib/python3.12/site-packages/airflow/models/taskinstance.py", line 3006, in _run_raw_task
    return _run_raw_task(
           ^^^^^^^^^^^^^^
  File "/home/airflow/.local/lib/python3.12/site-packages/airflow/models/taskinstance.py", line 274, in _run_raw_task
    TaskInstance._execute_task_with_callbacks(
  File "/home/airflow/.local/lib/python3.12/site-packages/airflow/models/taskinstance.py", line 3161, in _execute_task_with_callbacks
    result = self._execute_task(context, task_orig)
             ^^^^^^^^^^^^^^^^^^^^^^^^^^^^^^^^^^^^^^
  File "/home/airflow/.local/lib/python3.12/site-packages/airflow/models/taskinstance.py", line 3185, in _execute_task
    return _execute_task(self, context, task_orig)
           ^^^^^^^^^^^^^^^^^^^^^^^^^^^^^^^^^^^^^^^
  File "/home/airflow/.local/lib/python3.12/site-packages/airflow/models/taskinstance.py", line 768, in _execute_task
    result = _execute_callable(context=context, **execute_callable_kwargs)
             ^^^^^^^^^^^^^^^^^^^^^^^^^^^^^^^^^^^^^^^^^^^^^^^^^^^^^^^^^^^^^
  File "/home/airflow/.local/lib/python3.12/site-packages/airflow/models/taskinstance.py", line 734, in _execute_callable
    return ExecutionCallableRunner(
           ^^^^^^^^^^^^^^^^^^^^^^^^
  File "/home/airflow/.local/lib/python3.12/site-packages/airflow/utils/operator_helpers.py", line 252, in run
    return self.func(*args, **kwargs)
           ^^^^^^^^^^^^^^^^^^^^^^^^^^
  File "/home/airflow/.local/lib/python3.12/site-packages/airflow/models/baseoperator.py", line 424, in wrapper
    return func(self, *args, **kwargs)
           ^^^^^^^^^^^^^^^^^^^^^^^^^^^
  File "/home/airflow/.local/lib/python3.12/site-packages/airflow/sensors/filesystem.py", line 123, in execute
    super().execute(context=context)
  File "/home/airflow/.local/lib/python3.12/site-packages/airflow/models/baseoperator.py", line 424, in wrapper
    return func(self, *args, **kwargs)
           ^^^^^^^^^^^^^^^^^^^^^^^^^^^
  File "/home/airflow/.local/lib/python3.12/site-packages/airflow/sensors/base.py", line 326, in execute
    raise AirflowSensorTimeout(message)
airflow.exceptions.AirflowSensorTimeout: Sensor has timed out; run duration of 300.05189934699956 seconds exceeds the specified timeout of 300.0.
[2025-03-01T09:13:48.004+0000] {local_task_job_runner.py:266} INFO - Task exited with return code 1
[2025-03-01T09:13:48.040+0000] {taskinstance.py:3901} INFO - 0 downstream tasks scheduled from follow-on schedule check
[2025-03-01T09:13:48.046+0000] {local_task_job_runner.py:245} INFO - ::endgroup::
